Workbook

Sheet Master Tracking Ledger
A1: MASTER TRACKING LEDGER | LLM CTI Executive Report Evaluation
A2: Researcher: Arcadio Aguilar | Advisor: John Hally | RPC: Dr. Johannes Ullrich | ⚠ SECURED – Keep separate from evaluation workspace | Records: R_0001 – R_1000
A3: Report_ID | B3: Random_ID | C3: Prompt_Strategy | D3: Scenario_ID | E3: Incident_Category | F3: Iteration | G3: Source_Vendor | H3: Date_Generated | I3: Generation_Time_Sec | J3: Tokens_Per_Second (tok/s) | K3: Model | L3: Temperature | M3: Scoring_Status
A4: R_S0_SC01_I01 | B4: R_0667 | C4: Baseline – Zero-Shot (minimal instruction) | D4: SC01 | E4: Ransomware | F4: 1 | G4: Gemma3:27b via Ollama | H4: 46152 | I4: 9.079 | J4: 62.45 | K4: Gemma3:27b | L4: 0.3 | M4: Complete
A5: R_S0_SC01_I02 | B5: R_0573 | C5: Baseline – Zero-Shot (minimal instruction) | D5: SC01 | E5: Ransomware | F5: 2 | G5: Gemma3:27b via Ollama | H5: 46152 | I5: 8.371 | J5: 67.97 | K5: Gemma3:27b | L5: 0.3 | M5: Complete
A6: R_S0_SC01_I03 | B6: R_0732 | C6: Baseline – Zero-Shot (minimal instruction) | D6: SC01 | E6: Ransomware | F6: 3 | G6: Gemma3:27b via Ollama | H6: 46152 | I6: 12.223 | J6: 67.58 | K6: Gemma3:27b | L6: 0.3 | M6: Complete
A7: R_S0_SC01_I04 | B7: R_0335 | C7: Baseline – Zero-Shot (minimal instruction) | D7: SC01 | E7: Ransomware | F7: 4 | G7: Gemma3:27b via Ollama | H7: 46152 | I7: 11.759 | J7: 66.67 | K7: Gemma3:27b | L7: 0.3 | M7: Complete
A8: R_S0_SC01_I05 | B8: R_0733 | C8: Baseline – Zero-Shot (minimal instruction) | D8: SC01 | E8: Ransomware | F8: 5 | G8: Gemma3:27b via Ollama | H8: 46152 | I8: 12.856 | J8: 65.03 | K8: Gemma3:27b | L8: 0.3 | M8: Complete
A9: R_S0_SC01_I06 | B9: R_0502 | C9: Baseline – Zero-Shot (minimal instruction) | D9: SC01 | E9: Ransomware | F9: 6 | G9: Gemma3:27b via Ollama | H9: 46152 | I9: 12.476 | J9: 66.05 | K9: Gemma3:27b | L9: 0.3 | M9: Complete
A10: R_S0_SC01_I07 | B10: R_0638 | C10: Baseline – Zero-Shot (minimal instruction) | D10: SC01 | E10: Ransomware | F10: 7 | G10: Gemma3:27b via Ollama | H10: 46152 | I10: 12.823 | J10: 66.13 | K10: Gemma3:27b | L10: 0.3 | M10: Complete
A11: R_S0_SC01_I08 | B11: R_0636 | C11: Baseline – Zero-Shot (minimal instruction) | D11: SC01 | E11: Ransomware | F11: 8 | G11: Gemma3:27b via Ollama | H11: 46152 | I11: 12.096 | J11: 65.89 | K11: Gemma3:27b | L11: 0.3 | M11: Complete
A12: R_S0_SC01_I09 | B12: R_0054 | C12: Baseline – Zero-Shot (minimal instruction) | D12: SC01 | E12: Ransomware | F12: 9 | G12: Gemma3:27b via Ollama | H12: 46152 | I12: 11.648 | J12: 66.10 | K12: Gemma3:27b | L12: 0.3 | M12: Complete
A13: R_S0_SC01_I10 | B13: R_0834 | C13: Baseline – Zero-Shot (minimal instruction) | D13: SC01 | E13: Ransomware | F13: 10 | G13: Gemma3:27b via Ollama | H13: 46152 | I13: 12.940 | J13: 66.38 | K13: Gemma3:27b | L13: 0.3 | M13: Complete
A14: R_S0_SC02_I01 | B14: R_0720 | C14: Baseline – Zero-Shot (minimal instruction) | D14: SC02 | E14: Ransomware | F14: 1 | G14: Gemma3:27b via Ollama | H14: 46152 | I14: 13.571 | J14: 65.95 | K14: Gemma3:27b | L14: 0.3 | M14: Complete
A15: R_S0_SC02_I02 | B15: R_0534 | C15: Baseline – Zero-Shot (minimal instruction) | D15: SC02 | E15: Ransomware | F15: 2 | G15: Gemma3:27b via Ollama | H15: 46152 | I15: 11.953 | J15: 66.01 | K15: Gemma3:27b | L15: 0.3 | M15: Complete
... A1003: B_S4_SC05_I10 | B1003: R_0605 | C1003: Strategy 4 – One-Shot + Template + BLUF | D1003: SC05 | E1003: Business Email Compromise | F1003: 10 | G1003: Gemma3:27b via Ollama | H1003: 46166 | I1003: 7.676 | J1003: 66.70 | K1003: Gemma3:27b | L1003: 0.3 | M1003: Complete

Sheet Blind Scoring Sheet
A1: BLIND SCORING SHEET | Evaluators see Random_ID only – NO metadata
A2: Score each report on Random_ID only. Complete ALL scoring before consulting Master Tracking Ledger. Pass threshold: Composite ≥ 3.5 / 5.0
A3: Random_ID | B3: Actionability (Raw /5.0) | C3: Actionability Weighted (×0.35) | D3: Analytical Rigor (Raw /5.0) | E3: Analytical Rigor Weighted (×0.30) | F3: Language Appr. (Raw /5.0) | G3: Language Appr. Weighted (×0.20) | H3: Structure (Raw /5.0) | I3: Structure Weighted (×0.15) | J3: Composite Score | K3: Pass / Fail (≥3.5) | L3: Strengths | M3: Weaknesses | N3: Notes / Edge Cases
A4: R_0001 | B4: 3.1 | C4: 1.085 | D4: 3.4 | E4: 1.02 | F4: 3.8 | G4: 0.76 | H4: 3 | I4: 0.45 | J4: 3.32 | K4: Fail
A5: R_0002 | B5: 3.2 | C5: 1.12 | D5: 3.1 | E5: 0.93 | F5: 3.8 | G5: 0.76 | H5: 3 | I5: 0.45 | J5: 3.26 | K5: Fail
A6: R_0003 | B6: 3.8 | C6: 1.33 | D6: 3.4 | E6: 1.02 | F6: 4 | G6: 0.8 | H6: 3.2 | I6: 0.48 | J6: 3.63 | K6: Pass
A7: R_0004 | B7: 4 | C7: 1.4 | D7: 3.6 | E7: 1.08 | F7: 4.2 | G7: 0.84 | H7: 4 | I7: 0.6 | J7: 3.92 | K7: Pass
A8: R_0005 | B8: 3.4 | C8: 1.19 | D8: 2.8 | E8: 0.84 | F8: 3.2 | G8: 0.64 | H8: 2.8 | I8: 0.42 | J8: 3.09 | K8: Fail
A9: R_0006 | B9: 3.5 | C9: 1.225 | D9: 3.3 | E9: 0.99 | F9: 3.8 | G9: 0.76 | H9: 2.8 | I9: 0.42 | J9: 3.39 | K9: Fail
A10: R_0007 | B10: 3.8 | C10: 1.33 | D10: 3.2 | E10: 0.96 | F10: 3.8 | G10: 0.76 | H10: 3.8 | I10: 0.57 | J10: 3.62 | K10: Pass
A11: R_0008 | B11: 3.5 | C11: 1.225 | D11: 3.7 | E11: 1.11 | F11: 3.7 | G11: 0.74 | H11: 3.2 | I11: 0.48 | J11: 3.56 | K11: Pass
A12: R_0009 | B12: 2.7 | C12: 0.945 | D12: 3.2 | E12: 0.96 | F12: 3.5 | G12: 0.7 | H12: 3.7 | I12: 0.555 | J12: 3.16 | K12: Fail
A13: R_0010 | B13: 3.3 | C13: 1.155 | D13: 3.2 | E13: 0.96 | F13: 3.3 | G13: 0.66 | H13: 2.6 | I13: 0.39 | J13: 3.17 | K13: Fail
A14: R_0011 | B14: 3.5 | C14: 1.225 | D14: 3 | E14: 0.9 | F14: 3.6 | G14: 0.72 | H14: 2.8 | I14: 0.42 | J14: 3.26 | K14: Fail
A15: R_0012 | B15: 3.3 | C15: 1.155 | D15: 3.4 | E15: 1.02 | F15: 3.7 | G15: 0.74 | H15: 4.4 | I15: 0.66 | J15: 3.58 | K15: Pass
... A25: R_0022 | B25: 3.3 | C25: 1.155 | D25: 3.8 | E25: 1.14 | F25: 3.6 | G25: 0.72 | H25: 3.2 | I25: 0.48 | J25: 3.5 | K25: Pass
A26: R_0023 | B26: 3.6 | 2.3 | C26: 1.26 | .805 | D26: 3.0 | 2.2 | E26: 0.9 | 0.66 | F26: 3.7 | 2.2 | G26: 0.74 | 0.44 | H26: 3.6 | 3.7 | I26: 0.54 | .555 | J26: 3.44 | 2.42 | K26: Fail | Fail
A27: R_0024 | B27: 2.6 | C27: 0.91 | D27: 3.2 | E27: 0.96 | F27: 3.3 | G27: 0.66 | H27: 2.8 | I27: 0.42 | J27: 2.95 | K27: Fail
A28: R_0025 | B28: 3.5 | C28: 1.225 | D28: 2.8 | E28: 0.84 | F28: 3.6 | G28: 0.72 | H28: 3.6 | I28: 0.54 | J28: 3.33 | K28: Fail
A29: R_0026 | B29: 3 | C29: 1.05 | D29: 3 | E29: 0.9 | F29: 3.7 | G29: 0.74 | H29: 4.2 | I29: 0.63 | J29: 3.32 | K29: Fail
A30: R_0027 | B30: 3 | C30: 1.05 | D30: 3 | E30: 0.9 | F30: 3.7 | G30: 0.74 | H30: 3 | I30: 0.45 | J30: 3.14 | K30: Fail
A31: R_0028 | B31: 3.2 | C31: 1.12 | D31: 3.4 | E31: 1.02 | F31: 3.8 | G31: 0.76 | H31: 4.4 | I31: 0.66 | J31: 3.56 | K31: Pass
A32: R_0029 | B32: 3.7 | C32: 1.295 | D32: 3.5 | E32: 1.05 | F32: 3.5 | G32: 0.7 | H32: 3 | I32: 0.45 | J32: 3.5 | K32: Pass
A33: R_0030 | B33: 3.5 | C33: 1.225 | D33: 3.5 | E33: 1.05 | F33: 3.9 | G33: 0.78 | H33: 3 | I33: 0.45 | J33: 3.51 | K33: Pass
A34: R_0031 | B34: 3.1 | C34: 1.085 | D34: 3.4 | E34: 1.02 | F34: 3.8 | G34: 0.76 | H34: 4.4 | I34: 0.66 | J34: 3.53 | K34: Pass
A35: R_0032 | B35: 3.4 | C35: 1.19 | D35: 3.1 | E35: 0.93 | F35: 3.8 | G35: 0.76 | H35: 3.2 | I35: 0.48 | J35: 3.36 | K35: Fail
A36: R_0033 | B36: 3.2 | C36: 1.12 | D36: 3.6 | E36: 1.08 | F36: 3.8 | G36: 0.76 | H36: 4.4 | I36: 0.66 | J36: 3.62 | K36: Pass
A37: R_0034 | B37: 3.6 | C37: 1.26 | D37: 3.4 | E37: 1.02 | F37: 3.4 | G37: 0.68 | H37: 2.8 | I37: 0.42 | J37: 3.38 | K37: Fail
A38: R_0035 | B38: 3.6 | C38: 1.26 | D38: 3.8 | E38: 1.14 | F38: 3.4 | G38: 0.68 | H38: 3 | I38: 0.45 | J38: 3.53 | K38: Pass
A39: R_0036 | B39: 3.3 | C39: 1.155 | D39: 2.9 | E39: 0.87 | F39: 3.6 | G39: 0.72 | H39: 3.4 | I39: 0.51 | J39: 3.25 | K39: Fail
A40: R_0037 | B40: 3.6 | 3.5 | C40: 1.26 | 1.225 | D40: 3.2 | 2.2 | E40: 0.96 | 0.66 | F40: 3.8 | 2.9 | G40: 0.76 | 0.58 | H40: 3.6 | 3.9 | I40: 0.54 | 0.585 | J40: 3.52 | 3.05 | K40: Pass | Fail
A41: R_0038 | B41: 3.2 | C41: 1.12 | D41: 3.9 | E41: 1.17 | F41: 3.5 | G41: 0.7 | H41: 2.8 | I41: 0.42 | J41: 3.41 | K41: Fail
A42: R_0039 | B42: 3.2 | C42: 1.12 | D42: 3 | E42: 0.9 | F42: 3.4 | G42: 0.68 | H42: 2.6 | I42: 0.39 | J42: 3.09 | K42: Fail
A43: R_0040 | B43: 3.6 | C43: 1.26 | D43: 3 | E43: 0.9 | F43: 3.7 | G43: 0.74 | H43: 3.6 | I43: 0.54 | J43: 3.44 | K43: Fail
A44: R_0041 | B44: 3.3 | C44: 1.155 | D44: 3.7 | E44: 1.11 | F44: 3.8 | G44: 0.76 | H44: 3.2 | I44: 0.48 | J44: 3.5 | K44: Pass
A45: R_0042 | B45: 3.3 | C45: 1.155 | D45: 2.8 | E45: 0.84 | F45: 3.5 | G45: 0.7 | H45: 2.8 | I45: 0.42 | J45: 3.12 | K45: Fail
A46: R_0043 | B46: 3.5 | C46: 1.225 | D46: 3 | E46: 0.9 | F46: 3.8 | G46: 0.76 | H46: 3.6 | I46: 0.54 | J46: 3.42 | K46: Fail
A47: R_0044 | B47: 3.7 | C47: 1.295 | D47: 3.5 | E47: 1.05 | F47: 3.7 | G47: 0.74 | H47: 3.6 | I47: 0.54 | J47: 3.62 | K47: Pass
A48: R_0045 | B48: 3.9 | C48: 1.365 | D48: 2.8 | E48: 0.84 | F48: 4 | G48: 0.8 | H48: 4 | I48: 0.6 | J48: 3.6 | K48: Pass
A49: R_0046 | B49: 3.4 | C49: 1.19 | D49: 3.1 | E49: 0.93 | F49: 3.7 | G49: 0.74 | H49: 3.4 | I49: 0.51 | J49: 3.37 | K49: Fail
...

Sheet Analysis Dashboard
A1: ANALYSIS DASHBOARD | Post-Evaluation – Link scores after blinding period ends
A2: Complete this sheet ONLY after all blind scoring is finished and scores have been merged back to Master Tracking Ledger.
A3: Group | B3: N Reports | C3: Avg Actionability | D3: Avg Analytical Rigor | E3: Avg Language Appr. | F3: Avg Structure | G3: Avg Composite | H3: Std Dev Composite | I3: Pass Rate (%) | J3: Threshold Attainment Rate (%) | K3: Notes
A4: Baseline – Zero-Shot (S0) | B4: =COUNTIF('Dashboard Calc'!$B$4:$B$1003,"S0") | C4: =AVERAGEIF('Dashboard Calc'!$B$4:$B$1003,"S0",'Dashboard Calc'!$C$4:$C$1003) | D4: =AVERAGEIF('Dashboard Calc'!$B$4:$B$1003,"S0",'Dashboard Calc'!$D$4:$D$1003) | E4: =AVERAGEIF('Dashboard Calc'!$B$4:$B$1003,"S0",'Dashboard Calc'!$E$4:$E$1003) | F4: =AVERAGEIF('Dashboard Calc'!$B$4:$B$1003,"S0",'Dashboard Calc'!$F$4:$F$1003) | G4: =AVERAGEIF('Dashboard Calc'!$B$4:$B$1003,"S0",'Dashboard Calc'!$G$4:$G$1003) | H4: {=STDEV(IF('Dashboard Calc'!$B$4:$B$1003="S0",'Dashboard Calc'!$G$4:$G$1003))} | I4: =COUNTIFS('Dashboard Calc'!$B$4:$B$1003,"S0",'Dashboard Calc'!$H$4:$H$1003,"Pass")/COUNTIF('Dashboard Calc'!$B$4:$B$1003,"S0") | J4: =COUNTIFS('Dashboard Calc'!$B$4:$B$1003,"S0",'Dashboard Calc'!$G$4:$G$1003,">=3.5")/COUNTIF('Dashboard Calc'!$B$4:$B$1003,"S0")
A5: Strategy 1 – Zero-Shot + Template (S1) | B5: =COUNTIF('Dashboard Calc'!$B$4:$B$1003,"S1") | C5: =AVERAGEIF('Dashboard Calc'!$B$4:$B$1003,"S1",'Dashboard Calc'!$C$4:$C$1003) | D5: =AVERAGEIF('Dashboard Calc'!$B$4:$B$1003,"S1",'Dashboard Calc'!$D$4:$D$1003) | E5: =AVERAGEIF('Dashboard Calc'!$B$4:$B$1003,"S1",'Dashboard Calc'!$E$4:$E$1003) | F5: =AVERAGEIF('Dashboard Calc'!$B$4:$B$1003,"S1",'Dashboard Calc'!$F$4:$F$1003) | G5: =AVERAGEIF('Dashboard Calc'!$B$4:$B$1003,"S1",'Dashboard Calc'!$G$4:$G$1003) | H5: {=STDEV(IF('Dashboard Calc'!$B$4:$B$1003="S1",'Dashboard Calc'!$G$4:$G$1003))} | I5: =COUNTIFS('Dashboard Calc'!$B$4:$B$1003,"S1",'Dashboard Calc'!$H$4:$H$1003,"Pass")/COUNTIF('Dashboard Calc'!$B$4:$B$1003,"S1") | J5: =COUNTIFS('Dashboard Calc'!$B$4:$B$1003,"S1",'Dashboard Calc'!$G$4:$G$1003,">=3.5")/COUNTIF('Dashboard Calc'!$B$4:$B$1003,"S1")
A6: Strategy 2 – Zero-Shot + Template + BLUF (S2) | B6: =COUNTIF('Dashboard Calc'!$B$4:$B$1003,"S2") | C6: =AVERAGEIF('Dashboard Calc'!$B$4:$B$1003,"S2",'Dashboard Calc'!$C$4:$C$1003) | D6: =AVERAGEIF('Dashboard Calc'!$B$4:$B$1003,"S2",'Dashboard Calc'!$D$4:$D$1003) | E6: =AVERAGEIF('Dashboard Calc'!$B$4:$B$1003,"S2",'Dashboard Calc'!$E$4:$E$1003) | F6: =AVERAGEIF('Dashboard Calc'!$B$4:$B$1003,"S2",'Dashboard Calc'!$F$4:$F$1003) | G6: =AVERAGEIF('Dashboard Calc'!$B$4:$B$1003,"S2",'Dashboard Calc'!$G$4:$G$1003) | H6: {=STDEV(IF('Dashboard Calc'!$B$4:$B$1003="S2",'Dashboard Calc'!$G$4:$G$1003))} | I6: =COUNTIFS('Dashboard Calc'!$B$4:$B$1003,"S2",'Dashboard Calc'!$H$4:$H$1003,"Pass")/COUNTIF('Dashboard Calc'!$B$4:$B$1003,"S2") | J6: =COUNTIFS('Dashboard Calc'!$B$4:$B$1003,"S2",'Dashboard Calc'!$G$4:$G$1003,">=3.5")/COUNTIF('Dashboard Calc'!$B$4:$B$1003,"S2")
A7: Strategy 3 – One-Shot + Template (S3) | B7: =COUNTIF('Dashboard Calc'!$B$4:$B$1003,"S3") | C7: =AVERAGEIF('Dashboard Calc'!$B$4:$B$1003,"S3",'Dashboard Calc'!$C$4:$C$1003) | D7: =AVERAGEIF('Dashboard Calc'!$B$4:$B$1003,"S3",'Dashboard Calc'!$D$4:$D$1003) | E7: =AVERAGEIF('Dashboard Calc'!$B$4:$B$1003,"S3",'Dashboard Calc'!$E$4:$E$1003) | F7: =AVERAGEIF('Dashboard Calc'!$B$4:$B$1003,"S3",'Dashboard Calc'!$F$4:$F$1003) | G7: =AVERAGEIF('Dashboard Calc'!$B$4:$B$1003,"S3",'Dashboard Calc'!$G$4:$G$1003) | H7: {=STDEV(IF('Dashboard Calc'!$B$4:$B$1003="S3",'Dashboard Calc'!$G$4:$G$1003))} | I7: =COUNTIFS('Dashboard Calc'!$B$4:$B$1003,"S3",'Dashboard Calc'!$H$4:$H$1003,"Pass")/COUNTIF('Dashboard Calc'!$B$4:$B$1003,"S3") | J7: =COUNTIFS('Dashboard Calc'!$B$4:$B$1003,"S3",'Dashboard Calc'!$G$4:$G$1003,">=3.5")/COUNTIF('Dashboard Calc'!$B$4:$B$1003,"S3")
A8: Strategy 4 – One-Shot + Template + BLUF (S4) | B8: =COUNTIF('Dashboard Calc'!$B$4:$B$1003,"S4") | C8: =AVERAGEIF('Dashboard Calc'!$B$4:$B$1003,"S4",'Dashboard Calc'!$C$4:$C$1003) | D8: =AVERAGEIF('Dashboard Calc'!$B$4:$B$1003,"S4",'Dashboard Calc'!$D$4:$D$1003) | E8: =AVERAGEIF('Dashboard Calc'!$B$4:$B$1003,"S4",'Dashboard Calc'!$E$4:$E$1003) | F8: =AVERAGEIF('Dashboard Calc'!$B$4:$B$1003,"S4",'Dashboard Calc'!$F$4:$F$1003) | G8: =AVERAGEIF('Dashboard Calc'!$B$4:$B$1003,"S4",'Dashboard Calc'!$G$4:$G$1003) | H8: {=STDEV(IF('Dashboard Calc'!$B$4:$B$1003="S4",'Dashboard Calc'!$G$4:$G$1003))} | I8: =COUNTIFS('Dashboard Calc'!$B$4:$B$1003,"S4",'Dashboard Calc'!$H$4:$H$1003,"Pass")/COUNTIF('Dashboard Calc'!$B$4:$B$1003,"S4") | J8: =COUNTIFS('Dashboard Calc'!$B$4:$B$1003,"S4",'Dashboard Calc'!$G$4:$G$1003,">=3.5")/COUNTIF('Dashboard Calc'!$B$4:$B$1003,"S4")
A10: TIME SAVINGS ANALYSIS
A11: Metric | B11: Value | C11: Notes
A12: Human avg. time per report (hrs) | B12: 8 | C12: 4–12 hrs/report
A13: AI avg. generation time (sec) | B13: =SUMPRODUCT(IFERROR(VALUE('Master Tracking Ledger'!$I$4:$I$1003),0))/SUMPRODUCT(IFERROR(VALUE('Master Tracking Ledger'!$I$4:$I$1003)^0,0)) | C13: Record during each generation session
A14: AI avg. generation time (min) | B14: {=IF(B13="","",B13/60)} | C14: Auto-calculated from seconds
A15: Time saved per report (hrs) | B15: {=IF(B12="","",B12-B14)} | C15: Human hrs minus AI time in hrs
A16: Reports per week (CTI team) | B16: 2 | C16: Assumption: 2 reports/week
A17: Weekly hours saved | B17: {=IF(B15="","",B15*B16)} | C17: Time saved × reports per week
A18: Annual hours saved | B18: {=IF(B17="","",B17*52)} | C18: Weekly saved × 52 weeks
A20: MODEL PERFORMANCE METRICS (tok/s)
A21: Metric | B21: Value | C21: Notes
A22: Avg Tokens/Second across all runs | B22: =SUMPRODUCT(IFERROR(VALUE('Master Tracking Ledger'!$J$4:$J$1003),0))/SUMPRODUCT(IFERROR(VALUE('Master Tracking Ledger'!$J$4:$J$1003)^0,0)) | C22: Average tok/s from Master Tracking Ledger
A23: Min tok/s observed | B23: 60.9 | C23: Slowest generation recorded
A24: Max tok/s observed | B24: 68.59 | C24: Fastest generation recorded
A25: Avg tok/s by Strategy (S0) | B25: =SUMPRODUCT(--ISNUMBER(SEARCH("_S0_",'Master Tracking Ledger'!$A$4:$A$1003)),IFERROR(VALUE('Master Tracking Ledger'!$J$4:$J$1003),0))/SUMPRODUCT(--ISNUMBER(SEARCH("_S0_",'Master Tracking Ledger'!$A$4:$A$1003)),IFERROR(VALUE('Master Tracking Ledger'!$J$4:$J$1003)^0,0))
A26: Avg tok/s by Strategy (S1) | B26: =SUMPRODUCT(--ISNUMBER(SEARCH("_S1_",'Master Tracking Ledger'!$A$4:$A$1003)),IFERROR(VALUE('Master Tracking Ledger'!$J$4:$J$1003),0))/SUMPRODUCT(--ISNUMBER(SEARCH("_S1_",'Master Tracking Ledger'!$A$4:$A$1003)),IFERROR(VALUE('Master Tracking Ledger'!$J$4:$J$1003)^0,0))
A27: Avg tok/s by Strategy (S2) | B27: =SUMPRODUCT(--ISNUMBER(SEARCH("_S2_",'Master Tracking Ledger'!$A$4:$A$1003)),IFERROR(VALUE('Master Tracking Ledger'!$J$4:$J$1003),0))/SUMPRODUCT(--ISNUMBER(SEARCH("_S2_",'Master Tracking Ledger'!$A$4:$A$1003)),IFERROR(VALUE('Master Tracking Ledger'!$J$4:$J$1003)^0,0))
A28: Avg tok/s by Strategy (S3) | B28: =SUMPRODUCT(--ISNUMBER(SEARCH("_S3_",'Master Tracking Ledger'!$A$4:$A$1003)),IFERROR(VALUE('Master Tracking Ledger'!$J$4:$J$1003),0))/SUMPRODUCT(--ISNUMBER(SEARCH("_S3_",'Master Tracking Ledger'!$A$4:$A$1003)),IFERROR(VALUE('Master Tracking Ledger'!$J$4:$J$1003)^0,0))
A29: Avg tok/s by Strategy (S4) | B29: =SUMPRODUCT(--ISNUMBER(SEARCH("_S4_",'Master Tracking Ledger'!$A$4:$A$1003)),IFERROR(VALUE('Master Tracking Ledger'!$J$4:$J$1003),0))/SUMPRODUCT(--ISNUMBER(SEARCH("_S4_",'Master Tracking Ledger'!$A$4:$A$1003)),IFERROR(VALUE('Master Tracking Ledger'!$J$4:$J$1003)^0,0))
A31: GEMMA3 vs HUMAN-ANALYST SCORE RECONCILIATION | 60 dual-scored reports
A32: Left of pipe = Gemma3 (model) score; right = human analyst. Δ = Human − Gemma3. Source detail on the "Score Reconciliation" sheet. Pass threshold: Composite ≥ 3.5.
A33: Metric | B33: Value | C33: Notes
A34: Dual-scored reports (N) | B34: =COUNT('Score Reconciliation'!$B$4:$B$63) | C34: Reports graded by both Gemma3 and a human analyst
A35: Pass/Fail rating changed (count) | B35: =COUNTIF('Score Reconciliation'!$U$4:$U$63,"Yes") | C35: Aggregate (composite) Pass/Fail flipped between raters
A36: Pass/Fail changed (% of dual-scored) | B36: =COUNTIF('Score Reconciliation'!$U$4:$U$63,"Yes")/COUNT('Score Reconciliation'!$B$4:$B$63) | C36: Share of dual-scored reports whose verdict flipped
A37: — Gemma3 Pass → Human Fail | B37: =COUNTIFS('Score Reconciliation'!$S$4:$S$63,"Pass",'Score Reconciliation'!$T$4:$T$63,"Fail") | C37: Model passed; human failed (model over-credit)
A38: — Gemma3 Fail → Human Pass | B38: =COUNTIFS('Score Reconciliation'!$S$4:$S$63,"Fail",'Score Reconciliation'!$T$4:$T$63,"Pass") | C38: Model failed; human passed (model under-credit)
A39: Pass/Fail agreement rate (%) | B39: =COUNTIF('Score Reconciliation'!$U$4:$U$63,"No")/COUNT('Score Reconciliation'!$B$4:$B$63) | C39: Both raters reached the same verdict
A40: Mean composite — Gemma3 | B40: =AVERAGE('Score Reconciliation'!$O$4:$O$63) | C40: Average model composite across dual-scored set
A41: Mean composite — Human | B41: =AVERAGE('Score Reconciliation'!$P$4:$P$63) | C41: Average human composite across dual-scored set
A42: Mean composite Δ (Human − Gemma3) | B42: =AVERAGE('Score Reconciliation'!$Q$4:$Q$63) | C42: Signed: negative = human scored lower than model
A43: Mean |composite Δ| | B43: =AVERAGE('Score Reconciliation'!$R$4:$R$63) | C43: Average magnitude of disagreement, ignoring direction
...

Sheet Anonymization Key
A1: ANONYMIZATION KEY | ⚠ RESTRICTED
A2: Open ONLY after all evaluations are complete. Maps every Random_ID to its Report_ID, strategy, and metadata.
A3: Random_ID | B3: Report_ID | C3: Prompt_Strategy | D3: Scenario_ID | E3: Incident_Category
A4: R_0001 | B4: B_S3_SC05_I06 | C4: Strategy 3 – One-Shot + Structured Template | D4: SC05 | E4: Business Email Compromise
A5: R_0002 | B5: S_S0_SC04_I02 | C5: Baseline – Zero-Shot (minimal instruction) | D5: SC04 | E5: Supply Chain
A6: R_0003 | B6: S_S3_SC02_I10 | C6: Strategy 3 – One-Shot + Structured Template | D6: SC02 | E6: Supply Chain
A7: R_0004 | B7: R_S4_SC02_I08 | C7: Strategy 4 – One-Shot + Template + BLUF | D7: SC02 | E7: Ransomware
A8: R_0005 | B8: Z_S0_SC04_I04 | C8: Baseline – Zero-Shot (minimal instruction) | D8: SC04 | E8: Zero-Day / Edge Device
A9: R_0006 | B9: R_S1_SC05_I09 | C9: Strategy 1 – Zero-Shot + Structured Template | D9: SC05 | E9: Ransomware
A10: R_0007 | B10: B_S4_SC03_I07 | C10: Strategy 4 – One-Shot + Template + BLUF | D10: SC03 | E10: Business Email Compromise
A11: R_0008 | B11: Z_S3_SC05_I02 | C11: Strategy 3 – One-Shot + Structured Template | D11: SC05 | E11: Zero-Day / Edge Device
A12: R_0009 | B12: B_S2_SC05_I04 | C12: Strategy 2 – Zero-Shot + Template + BLUF | D12: SC05 | E12: Business Email Compromise
A13: R_0010 | B13: R_S3_SC02_I04 | C13: Strategy 3 – One-Shot + Structured Template | D13: SC02 | E13: Ransomware
A14: R_0011 | B14: Z_S1_SC01_I08 | C14: Strategy 1 – Zero-Shot + Structured Template | D14: SC01 | E14: Zero-Day / Edge Device
... A1003: R_1000 | B1003: S_S2_SC05_I07 | C1003: Strategy 2 – Zero-Shot + Template + BLUF | D1003: SC05 | E1003: Supply Chain

Sheet Score Reconciliation
A1: SCORE RECONCILIATION | Gemma3 vs Human-Analyst dual-scored reports (parsed from Blind Scoring Sheet)
A2: Each row de-concatenates a "Gemma3 | Human" cell. Left of pipe = Gemma3 (model) score; right = human analyst. Δ = Human − Gemma3. Values are live formulas; edit the Blind Scoring Sheet and they update. Sort Key column is a unique tie-broken |Δ| used by the dashboard top-variance lookup.
A3: Random_ID | B3: Src Row | C3: Gemma3 Action | D3: Human Action | E3: Δ Action | F3: Gemma3 Rigor | G3: Human Rigor | H3: Δ Rigor | I3: Gemma3 Language | J3: Human Language | K3: Δ Language | L3: Gemma3 Structure | M3: Human Structure | N3: Δ Structure | O3: Gemma3 Composite | P3: Human Composite | Q3: Δ Composite (H−G) | R3: |Δ Composite| | S3: Gemma3 P/F | T3: Human P/F | U3: P/F Changed? | V3: Flip Direction | W3: Sort Key
A4: R_0023 | B4: 26 | C4: =VALUE(TRIM(LEFT('Blind Scoring Sheet'!B26,FIND("|",'Blind Scoring Sheet'!B26)-1))) | D4: =VALUE(TRIM(MID('Blind Scoring Sheet'!B26,FIND("|",'Blind Scoring Sheet'!B26)+1,20))) | E4: =D4-C4 | F4: =VALUE(TRIM(LEFT('Blind Scoring Sheet'!D26,FIND("|",'Blind Scoring Sheet'!D26)-1))) | G4: =VALUE(TRIM(MID('Blind Scoring Sheet'!D26,FIND("|",'Blind Scoring Sheet'!D26)+1,20))) | H4: =G4-F4 | I4: =VALUE(TRIM(LEFT('Blind Scoring Sheet'!F26,FIND("|",'Blind Scoring Sheet'!F26)-1))) | J4: =VALUE(TRIM(MID('Blind Scoring Sheet'!F26,FIND("|",'Blind Scoring Sheet'!F26)+1,20))) | K4: =J4-I4 | L4: =VALUE(TRIM(LEFT('Blind Scoring Sheet'!H26,FIND("|",'Blind Scoring Sheet'!H26)-1))) | M4: =VALUE(TRIM(MID('Blind Scoring Sheet'!H26,FIND("|",'Blind Scoring Sheet'!H26)+1,20))) | N4: =M4-L4 | O4: =VALUE(TRIM(LEFT('Blind Scoring Sheet'!J26,FIND("|",'Blind Scoring Sheet'!J26)-1))) | P4: =VALUE(TRIM(MID('Blind Scoring Sheet'!J26,FIND("|",'Blind Scoring Sheet'!J26)+1,20))) | Q4: =P4-O4 | R4: =ABS(Q4) | S4: =TRIM(LEFT('Blind Scoring Sheet'!K26,FIND("|",'Blind Scoring Sheet'!K26)-1)) | T4: =TRIM(MID('Blind Scoring Sheet'!K26,FIND("|",'Blind Scoring Sheet'!K26)+1,20)) | U4: =IF(S4=T4,"No","Yes") | V4: =IF(S4=T4,"— (agree)",S4&" → "&T4) | W4: =R4+ROW()/1000000
A5: R_0037 | B5: 40 | C5: =VALUE(TRIM(LEFT('Blind Scoring Sheet'!B40,FIND("|",'Blind Scoring Sheet'!B40)-1))) | D5: =VALUE(TRIM(MID('Blind Scoring Sheet'!B40,FIND("|",'Blind Scoring Sheet'!B40)+1,20))) | E5: =D5-C5 | F5: =VALUE(TRIM(LEFT('Blind Scoring Sheet'!D40,FIND("|",'Blind Scoring Sheet'!D40)-1))) | G5: =VALUE(TRIM(MID('Blind Scoring Sheet'!D40,FIND("|",'Blind Scoring Sheet'!D40)+1,20))) | H5: =G5-F5 | I5: =VALUE(TRIM(LEFT('Blind Scoring Sheet'!F40,FIND("|",'Blind Scoring Sheet'!F40)-1))) | J5: =VALUE(TRIM(MID('Blind Scoring Sheet'!F40,FIND("|",'Blind Scoring Sheet'!F40)+1,20))) | K5: =J5-I5 | L5: =VALUE(TRIM(LEFT('Blind Scoring Sheet'!H40,FIND("|",'Blind Scoring Sheet'!H40)-1))) | M5: =VALUE(TRIM(MID('Blind Scoring Sheet'!H40,FIND("|",'Blind Scoring Sheet'!H40)+1,20))) | N5: =M5-L5 | O5: =VALUE(TRIM(LEFT('Blind Scoring Sheet'!J40,FIND("|",'Blind Scoring Sheet'!J40)-1))) | P5: =VALUE(TRIM(MID('Blind Scoring Sheet'!J40,FIND("|",'Blind Scoring Sheet'!J40)+1,20))) | Q5: =P5-O5 | R5: =ABS(Q5) | S5: =TRIM(LEFT('Blind Scoring Sheet'!K40,FIND("|",'Blind Scoring Sheet'!K40)-1)) | T5: =TRIM(MID('Blind Scoring Sheet'!K40,FIND("|",'Blind Scoring Sheet'!K40)+1,20)) | U5: =IF(S5=T5,"No","Yes") | V5: =IF(S5=T5,"— (agree)",S5&" → "&T5) | W5: =R5+ROW()/1000000
A6: R_0093 | B6: 96 | C6: =VALUE(TRIM(LEFT('Blind Scoring Sheet'!B96,FIND("|",'Blind Scoring Sheet'!B96)-1))) | D6: =VALUE(TRIM(MID('Blind Scoring Sheet'!B96,FIND("|",'Blind Scoring Sheet'!B96)+1,20))) | E6: =D6-C6 | F6: =VALUE(TRIM(LEFT('Blind Scoring Sheet'!D96,FIND("|",'Blind Scoring Sheet'!D96)-1))) | G6: =VALUE(TRIM(MID('Blind Scoring Sheet'!D96,FIND("|",'Blind Scoring Sheet'!D96)+1,20))) | H6: =G6-F6 | I6: =VALUE(TRIM(LEFT('Blind Scoring Sheet'!F96,FIND("|",'Blind Scoring Sheet'!F96)-1))) | J6: =VALUE(TRIM(MID('Blind Scoring Sheet'!F96,FIND("|",'Blind Scoring Sheet'!F96)+1,20))) | K6: =J6-I6 | L6: =VALUE(TRIM(LEFT('Blind Scoring Sheet'!H96,FIND("|",'Blind Scoring Sheet'!H96)-1))) | M6: =VALUE(TRIM(MID('Blind Scoring Sheet'!H96,FIND("|",'Blind Scoring Sheet'!H96)+1,20))) | N6: =M6-L6 | O6: =VALUE(TRIM(LEFT('Blind Scoring Sheet'!J96,FIND("|",'Blind Scoring Sheet'!J96)-1))) | P6: =VALUE(TRIM(MID('Blind Scoring Sheet'!J96,FIND("|",'Blind Scoring Sheet'!J96)+1,20))) | Q6: =P6-O6 | R6: =ABS(Q6) | S6: =TRIM(LEFT('Blind Scoring Sheet'!K96,FIND("|",'Blind Scoring Sheet'!K96)-1)) | T6: =TRIM(MID('Blind Scoring Sheet'!K96,FIND("|",'Blind Scoring Sheet'!K96)+1,20)) | U6: =IF(S6=T6,"No","Yes") | V6: =IF(S6=T6,"— (agree)",S6&" → "&T6) | W6: =R6+ROW()/1000000
A7: R_0100 | B7: 103 | C7: =VALUE(TRIM(LEFT('Blind Scoring Sheet'!B103,FIND("|",'Blind Scoring Sheet'!B103)-1))) | D7: =VALUE(TRIM(MID('Blind Scoring Sheet'!B103,FIND("|",'Blind Scoring Sheet'!B103)+1,20))) | E7: =D7-C7 | F7: =VALUE(TRIM(LEFT('Blind Scoring Sheet'!D103,FIND("|",'Blind Scoring Sheet'!D103)-1))) | G7: =VALUE(TRIM(MID('Blind Scoring Sheet'!D103,FIND("|",'Blind Scoring Sheet'!D103)+1,20))) | H7: =G7-F7 | I7: =VALUE(TRIM(LEFT('Blind Scoring Sheet'!F103,FIND("|",'Blind Scoring Sheet'!F103)-1))) | J7: =VALUE(TRIM(MID('Blind Scoring Sheet'!F103,FIND("|",'Blind Scoring Sheet'!F103)+1,20))) | K7: =J7-I7 | L7: =VALUE(TRIM(LEFT('Blind Scoring Sheet'!H103,FIND("|",'Blind Scoring Sheet'!H103)-1))) | M7: =VALUE(TRIM(MID('Blind Scoring Sheet'!H103,FIND("|",'Blind Scoring Sheet'!H103)+1,20))) | N7: =M7-L7 | O7: =VALUE(TRIM(LEFT('Blind Scoring Sheet'!J103,FIND("|",'Blind Scoring Sheet'!J103)-1))) | P7: =VALUE(TRIM(MID('Blind Scoring Sheet'!J103,FIND("|",'Blind Scoring Sheet'!J103)+1,20))) | Q7: =P7-O7 | R7: =ABS(Q7) | S7: =TRIM(LEFT('Blind Scoring Sheet'!K103,FIND("|",'Blind Scoring Sheet'!K103)-1)) | T7: =TRIM(MID('Blind Scoring Sheet'!K103,FIND("|",'Blind Scoring Sheet'!K103)+1,20)) | U7: =IF(S7=T7,"No","Yes") | V7: =IF(S7=T7,"— (agree)",S7&" → "&T7) | W7: =R7+ROW()/1000000
A8: R_0120 | B8: 123 | C8: =VALUE(TRIM(LEFT('Blind Scoring Sheet'!B123,FIND("|",'Blind Scoring Sheet'!B123)-1))) | D8: =VALUE(TRIM(MID('Blind Scoring Sheet'!B123,FIND("|",'Blind Scoring Sheet'!B123)+1,20))) | E8: =D8-C8 | F8: =VALUE(TRIM(LEFT('Blind Scoring Sheet'!D123,FIND("|",'Blind Scoring Sheet'!D123)-1))) | G8: =VALUE(TRIM(MID('Blind Scoring Sheet'!D123,FIND("|",'Blind Scoring Sheet'!D123)+1,20))) | H8: =G8-F8 | I8: =VALUE(TRIM(LEFT('Blind Scoring Sheet'!F123,FIND("|",'Blind Scoring Sheet'!F123)-1))) | J8: =VALUE(TRIM(MID('Blind Scoring Sheet'!F123,FIND("|",'Blind Scoring Sheet'!F123)+1,20))) | K8: =J8-I8 | L8: =VALUE(TRIM(LEFT('Blind Scoring Sheet'!H123,FIND("|",'Blind Scoring Sheet'!H123)-1))) | M8: =VALUE(TRIM(MID('Blind Scoring Sheet'!H123,FIND("|",'Blind Scoring Sheet'!H123)+1,20))) | N8: =M8-L8 | O8: =VALUE(TRIM(LEFT('Blind Scoring Sheet'!J123,FIND("|",'Blind Scoring Sheet'!J123)-1))) | P8: =VALUE(TRIM(MID('Blind Scoring Sheet'!J123,FIND("|",'Blind Scoring Sheet'!J123)+1,20))) | Q8: =P8-O8 | R8: =ABS(Q8) | S8: =TRIM(LEFT('Blind Scoring Sheet'!K123,FIND("|",'Blind Scoring Sheet'!K123)-1)) | T8: =TRIM(MID('Blind Scoring Sheet'!K123,FIND("|",'Blind Scoring Sheet'!K123)+1,20)) | U8: =IF(S8=T8,"No","Yes") | V8: =IF(S8=T8,"— (agree)",S8&" → "&T8) | W8: =R8+ROW()/1000000
A9: R_0134 | B9: 137 | C9: =VALUE(TRIM(LEFT('Blind Scoring Sheet'!B137,FIND("|",'Blind Scoring Sheet'!B137)-1))) | D9: =VALUE(TRIM(MID('Blind Scoring Sheet'!B137,FIND("|",'Blind Scoring Sheet'!B137)+1,20))) | E9: =D9-C9 | F9: =VALUE(TRIM(LEFT('Blind Scoring Sheet'!D137,FIND("|",'Blind Scoring Sheet'!D137)-1))) | G9: =VALUE(TRIM(MID('Blind Scoring Sheet'!D137,FIND("|",'Blind Scoring Sheet'!D137)+1,20))) | H9: =G9-F9 | I9: =VALUE(TRIM(LEFT('Blind Scoring Sheet'!F137,FIND("|",'Blind Scoring Sheet'!F137)-1))) | J9: =VALUE(TRIM(MID('Blind Scoring Sheet'!F137,FIND("|",'Blind Scoring Sheet'!F137)+1,20))) | K9: =J9-I9 | L9: =VALUE(TRIM(LEFT('Blind Scoring Sheet'!H137,FIND("|",'Blind Scoring Sheet'!H137)-1))) | M9: =VALUE(TRIM(MID('Blind Scoring Sheet'!H137,FIND("|",'Blind Scoring Sheet'!H137)+1,20))) | N9: =M9-L9 | O9: =VALUE(TRIM(LEFT('Blind Scoring Sheet'!J137,FIND("|",'Blind Scoring Sheet'!J137)-1))) | P9: =VALUE(TRIM(MID('Blind Scoring Sheet'!J137,FIND("|",'Blind Scoring Sheet'!J137)+1,20))) | Q9: =P9-O9 | R9: =ABS(Q9) | S9: =TRIM(LEFT('Blind Scoring Sheet'!K137,FIND("|",'Blind Scoring Sheet'!K137)-1)) | T9: =TRIM(MID('Blind Scoring Sheet'!K137,FIND("|",'Blind Scoring Sheet'!K137)+1,20)) | U9: =IF(S9=T9,"No","Yes") | V9: =IF(S9=T9,"— (agree)",S9&" → "&T9) | W9: =R9+ROW()/1000000
A10: R_0139 | B10: 142 | C10: =VALUE(TRIM(LEFT('Blind Scoring Sheet'!B142,FIND("|",'Blind Scoring Sheet'!B142)-1))) | D10: =VALUE(TRIM(MID('Blind Scoring Sheet'!B142,FIND("|",'Blind Scoring Sheet'!B142)+1,20))) | E10: =D10-C10 | F10: =VALUE(TRIM(LEFT('Blind Scoring Sheet'!D142,FIND("|",'Blind Scoring Sheet'!D142)-1))) | G10: =VALUE(TRIM(MID('Blind Scoring Sheet'!D142,FIND("|",'Blind Scoring Sheet'!D142)+1,20))) | H10: =G10-F10 | I10: =VALUE(TRIM(LEFT('Blind Scoring Sheet'!F142,FIND("|",'Blind Scoring Sheet'!F142)-1))) | J10: =VALUE(TRIM(MID('Blind Scoring Sheet'!F142,FIND("|",'Blind Scoring Sheet'!F142)+1,20))) | K10: =J10-I10 | L10: =VALUE(TRIM(LEFT('Blind Scoring Sheet'!H142,FIND("|",'Blind Scoring Sheet'!H142)-1))) | M10: =VALUE(TRIM(MID('Blind Scoring Sheet'!H142,FIND("|",'Blind Scoring Sheet'!H142)+1,20))) | N10: =M10-L10 | O10: =VALUE(TRIM(LEFT('Blind Scoring Sheet'!J142,FIND("|",'Blind Scoring Sheet'!J142)-1))) | P10: =VALUE(TRIM(MID('Blind Scoring Sheet'!J142,FIND("|",'Blind Scoring Sheet'!J142)+1,20))) | Q10: =P10-O10 | R10: =ABS(Q10) | S10: =TRIM(LEFT('Blind Scoring Sheet'!K142,FIND("|",'Blind Scoring Sheet'!K142)-1)) | T10: =TRIM(MID('Blind Scoring Sheet'!K142,FIND("|",'Blind Scoring Sheet'!K142)+1,20)) | U10: =IF(S10=T10,"No","Yes") | V10: =IF(S10=T10,"— (agree)",S10&" → "&T10) | W10: =R10+ROW()/1000000
A11: R_0171 | B11: 174 | C11: =VALUE(TRIM(LEFT('Blind Scoring Sheet'!B174,FIND("|",'Blind Scoring Sheet'!B174)-1))) | D11: =VALUE(TRIM(MID('Blind Scoring Sheet'!B174,FIND("|",'Blind Scoring Sheet'!B174)+1,20))) | E11: =D11-C11 | F11: =VALUE(TRIM(LEFT('Blind Scoring Sheet'!D174,FIND("|",'Blind Scoring Sheet'!D174)-1))) | G11: =VALUE(TRIM(MID('Blind Scoring Sheet'!D174,FIND("|",'Blind Scoring Sheet'!D174)+1,20))) | H11: =G11-F11 | I11: =VALUE(TRIM(LEFT('Blind Scoring Sheet'!F174,FIND("|",'Blind Scoring Sheet'!F174)-1))) | J11: =VALUE(TRIM(MID('Blind Scoring Sheet'!F174,FIND("|",'Blind Scoring Sheet'!F174)+1,20))) | K11: =J11-I11 | L11: =VALUE(TRIM(LEFT('Blind Scoring Sheet'!H174,FIND("|",'Blind Scoring Sheet'!H174)-1))) | M11: =VALUE(TRIM(MID('Blind Scoring Sheet'!H174,FIND("|",'Blind Scoring Sheet'!H174)+1,20))) | N11: =M11-L11 | O11: =VALUE(TRIM(LEFT('Blind Scoring Sheet'!J174,FIND("|",'Blind Scoring Sheet'!J174)-1))) | P11: =VALUE(TRIM(MID('Blind Scoring Sheet'!J174,FIND("|",'Blind Scoring Sheet'!J174)+1,20))) | Q11: =P11-O11 | R11: =ABS(Q11) | S11: =TRIM(LEFT('Blind Scoring Sheet'!K174,FIND("|",'Blind Scoring Sheet'!K174)-1)) | T11: =TRIM(MID('Blind Scoring Sheet'!K174,FIND("|",'Blind Scoring Sheet'!K174)+1,20)) | U11: =IF(S11=T11,"No","Yes") | V11: =IF(S11=T11,"— (agree)",S11&" → "&T11) | W11: =R11+ROW()/1000000
A12: R_0186 | B12: 189 | C12: =VALUE(TRIM(LEFT('Blind Scoring Sheet'!B189,FIND("|",'Blind Scoring Sheet'!B189)-1))) | D12: =VALUE(TRIM(MID('Blind Scoring Sheet'!B189,FIND("|",'Blind Scoring Sheet'!B189)+1,20))) | E12: =D12-C12 | F12: =VALUE(TRIM(LEFT('Blind Scoring Sheet'!D189,FIND("|",'Blind Scoring Sheet'!D189)-1))) | G12: =VALUE(TRIM(MID('Blind Scoring Sheet'!D189,FIND("|",'Blind Scoring Sheet'!D189)+1,20))) | H12: =G12-F12 | I12: =VALUE(TRIM(LEFT('Blind Scoring Sheet'!F189,FIND("|",'Blind Scoring Sheet'!F189)-1))) | J12: =VALUE(TRIM(MID('Blind Scoring Sheet'!F189,FIND("|",'Blind Scoring Sheet'!F189)+1,20))) | K12: =J12-I12 | L12: =VALUE(TRIM(LEFT('Blind Scoring Sheet'!H189,FIND("|",'Blind Scoring Sheet'!H189)-1))) | M12: =VALUE(TRIM(MID('Blind Scoring Sheet'!H189,FIND("|",'Blind Scoring Sheet'!H189)+1,20))) | N12: =M12-L12 | O12: =VALUE(TRIM(LEFT('Blind Scoring Sheet'!J189,FIND("|",'Blind Scoring Sheet'!J189)-1))) | P12: =VALUE(TRIM(MID('Blind Scoring Sheet'!J189,FIND("|",'Blind Scoring Sheet'!J189)+1,20))) | Q12: =P12-O12 | R12: =ABS(Q12) | S12: =TRIM(LEFT('Blind Scoring Sheet'!K189,FIND("|",'Blind Scoring Sheet'!K189)-1)) | T12: =TRIM(MID('Blind Scoring Sheet'!K189,FIND("|",'Blind Scoring Sheet'!K189)+1,20)) | U12: =IF(S12=T12,"No","Yes") | V12: =IF(S12=T12,"— (agree)",S12&" → "&T12) | W12: =R12+ROW()/1000000
A13: R_0190 | B13: 193 | C13: =VALUE(TRIM(LEFT('Blind Scoring Sheet'!B193,FIND("|",'Blind Scoring Sheet'!B193)-1))) | D13: =VALUE(TRIM(MID('Blind Scoring Sheet'!B193,FIND("|",'Blind Scoring Sheet'!B193)+1,20))) | E13: =D13-C13 | F13: =VALUE(TRIM(LEFT('Blind Scoring Sheet'!D193,FIND("|",'Blind Scoring Sheet'!D193)-1))) | G13: =VALUE(TRIM(MID('Blind Scoring Sheet'!D193,FIND("|",'Blind Scoring Sheet'!D193)+1,20))) | H13: =G13-F13 | I13: =VALUE(TRIM(LEFT('Blind Scoring Sheet'!F193,FIND("|",'Blind Scoring Sheet'!F193)-1))) | J13: =VALUE(TRIM(MID('Blind Scoring Sheet'!F193,FIND("|",'Blind Scoring Sheet'!F193)+1,20))) | K13: =J13-I13 | L13: =VALUE(TRIM(LEFT('Blind Scoring Sheet'!H193,FIND("|",'Blind Scoring Sheet'!H193)-1))) | M13: =VALUE(TRIM(MID('Blind Scoring Sheet'!H193,FIND("|",'Blind Scoring Sheet'!H193)+1,20))) | N13: =M13-L13 | O13: =VALUE(TRIM(LEFT('Blind Scoring Sheet'!J193,FIND("|",'Blind Scoring Sheet'!J193)-1))) | P13: =VALUE(TRIM(MID('Blind Scoring Sheet'!J193,FIND("|",'Blind Scoring Sheet'!J193)+1,20))) | Q13: =P13-O13 | R13: =ABS(Q13) | S13: =TRIM(LEFT('Blind Scoring Sheet'!K193,FIND("|",'Blind Scoring Sheet'!K193)-1)) | T13: =TRIM(MID('Blind Scoring Sheet'!K193,FIND("|",'Blind Scoring Sheet'!K193)+1,20)) | U13: =IF(S13=T13,"No","Yes") | V13: =IF(S13=T13,"— (agree)",S13&" → "&T13) | W13: =R13+ROW()/1000000
A14: R_0193 | B14: 196 | C14: =VALUE(TRIM(LEFT('Blind Scoring Sheet'!B196,FIND("|",'Blind Scoring Sheet'!B196)-1))) | D14: =VALUE(TRIM(MID('Blind Scoring Sheet'!B196,FIND("|",'Blind Scoring Sheet'!B196)+1,20))) | E14: =D14-C14 | F14: =VALUE(TRIM(LEFT('Blind Scoring Sheet'!D196,FIND("|",'Blind Scoring Sheet'!D196)-1))) | G14: =VALUE(TRIM(MID('Blind Scoring Sheet'!D196,FIND("|",'Blind Scoring Sheet'!D196)+1,20))) | H14: =G14-F14 | I14: =VALUE(TRIM(LEFT('Blind Scoring Sheet'!F196,FIND("|",'Blind Scoring Sheet'!F196)-1))) | J14: =VALUE(TRIM(MID('Blind Scoring Sheet'!F196,FIND("|",'Blind Scoring Sheet'!F196)+1,20))) | K14: =J14-I14 | L14: =VALUE(TRIM(LEFT('Blind Scoring Sheet'!H196,FIND("|",'Blind Scoring Sheet'!H196)-1))) | M14: =VALUE(TRIM(MID('Blind Scoring Sheet'!H196,FIND("|",'Blind Scoring Sheet'!H196)+1,20))) | N14: =M14-L14 | O14: =VALUE(TRIM(LEFT('Blind Scoring Sheet'!J196,FIND("|",'Blind Scoring Sheet'!J196)-1))) | P14: =VALUE(TRIM(MID('Blind Scoring Sheet'!J196,FIND("|",'Blind Scoring Sheet'!J196)+1,20))) | Q14: =P14-O14 | R14: =ABS(Q14) | S14: =TRIM(LEFT('Blind Scoring Sheet'!K196,FIND("|",'Blind Scoring Sheet'!K196)-1)) | T14: =TRIM(MID('Blind Scoring Sheet'!K196,FIND("|",'Blind Scoring Sheet'!K196)+1,20)) | U14: =IF(S14=T14,"No","Yes") | V14: =IF(S14=T14,"— (agree)",S14&" → "&T14) | W14: =R14+ROW()/1000000
A15: R_0205 | B15: 208 | C15: =VALUE(TRIM(LEFT('Blind Scoring Sheet'!B208,FIND("|",'Blind Scoring Sheet'!B208)-1))) | D15: =VALUE(TRIM(MID('Blind Scoring Sheet'!B208,FIND("|",'Blind Scoring Sheet'!B208)+1,20))) | E15: =D15-C15 | F15: =VALUE(TRIM(LEFT('Blind Scoring Sheet'!D208,FIND("|",'Blind Scoring Sheet'!D208)-1))) | G15: =VALUE(TRIM(MID('Blind Scoring Sheet'!D208,FIND("|",'Blind Scoring Sheet'!D208)+1,20))) | H15: =G15-F15 | I15: =VALUE(TRIM(LEFT('Blind Scoring Sheet'!F208,FIND("|",'Blind Scoring Sheet'!F208)-1))) | J15: =VALUE(TRIM(MID('Blind Scoring Sheet'!F208,FIND("|",'Blind Scoring Sheet'!F208)+1,20))) | K15: =J15-I15 | L15: =VALUE(TRIM(LEFT('Blind Scoring Sheet'!H208,FIND("|",'Blind Scoring Sheet'!H208)-1))) | M15: =VALUE(TRIM(MID('Blind Scoring Sheet'!H208,FIND("|",'Blind Scoring Sheet'!H208)+1,20))) | N15: =M15-L15 | O15: =VALUE(TRIM(LEFT('Blind Scoring Sheet'!J208,FIND("|",'Blind Scoring Sheet'!J208)-1))) | P15: =VALUE(TRIM(MID('Blind Scoring Sheet'!J208,FIND("|",'Blind Scoring Sheet'!J208)+1,20))) | Q15: =P15-O15 | R15: =ABS(Q15) | S15: =TRIM(LEFT('Blind Scoring Sheet'!K208,FIND("|",'Blind Scoring Sheet'!K208)-1)) | T15: =TRIM(MID('Blind Scoring Sheet'!K208,FIND("|",'Blind Scoring Sheet'!K208)+1,20)) | U15: =IF(S15=T15,"No","Yes") | V15: =IF(S15=T15,"— (agree)",S15&" → "&T15) | W15: =R15+ROW()/1000000
A16: R_0223 | B16: 226 | C16: =VALUE(TRIM(LEFT('Blind Scoring Sheet'!B226,FIND("|",'Blind Scoring Sheet'!B226)-1))) | D16: =VALUE(TRIM(MID('Blind Scoring Sheet'!B226,FIND("|",'Blind Scoring Sheet'!B226)+1,20))) | E16: =D16-C16 | F16: =VALUE(TRIM(LEFT('Blind Scoring Sheet'!D226,FIND("|",'Blind Scoring Sheet'!D226)-1))) | G16: =VALUE(TRIM(MID('Blind Scoring Sheet'!D226,FIND("|",'Blind Scoring Sheet'!D226)+1,20))) | H16: =G16-F16 | I16: =VALUE(TRIM(LEFT('Blind Scoring Sheet'!F226,FIND("|",'Blind Scoring Sheet'!F226)-1))) | J16: =VALUE(TRIM(MID('Blind Scoring Sheet'!F226,FIND("|",'Blind Scoring Sheet'!F226)+1,20))) | K16: =J16-I16 | L16: =VALUE(TRIM(LEFT('Blind Scoring Sheet'!H226,FIND("|",'Blind Scoring Sheet'!H226)-1))) | M16: =VALUE(TRIM(MID('Blind Scoring Sheet'!H226,FIND("|",'Blind Scoring Sheet'!H226)+1,20))) | N16: =M16-L16 | O16: =VALUE(TRIM(LEFT('Blind Scoring Sheet'!J226,FIND("|",'Blind Scoring Sheet'!J226)-1))) | P16: =VALUE(TRIM(MID('Blind Scoring Sheet'!J226,FIND("|",'Blind Scoring Sheet'!J226)+1,20))) | Q16: =P16-O16 | R16: =ABS(Q16) | S16: =TRIM(LEFT('Blind Scoring Sheet'!K226,FIND("|",'Blind Scoring Sheet'!K226)-1)) | T16: =TRIM(MID('Blind Scoring Sheet'!K226,FIND("|",'Blind Scoring Sheet'!K226)+1,20)) | U16: =IF(S16=T16,"No","Yes") | V16: =IF(S16=T16,"— (agree)",S16&" → "&T16) | W16: =R16+ROW()/1000000
A17: R_0232 | B17: 235 | C17: =VALUE(TRIM(LEFT('Blind Scoring Sheet'!B235,FIND("|",'Blind Scoring Sheet'!B235)-1))) | D17: =VALUE(TRIM(MID('Blind Scoring Sheet'!B235,FIND("|",'Blind Scoring Sheet'!B235)+1,20))) | E17: =D17-C17 | F17: =VALUE(TRIM(LEFT('Blind Scoring Sheet'!D235,FIND("|",'Blind Scoring Sheet'!D235)-1))) | G17: =VALUE(TRIM(MID('Blind Scoring Sheet'!D235,FIND("|",'Blind Scoring Sheet'!D235)+1,20))) | H17: =G17-F17 | I17: =VALUE(TRIM(LEFT('Blind Scoring Sheet'!F235,FIND("|",'Blind Scoring Sheet'!F235)-1))) | J17: =VALUE(TRIM(MID('Blind Scoring Sheet'!F235,FIND("|",'Blind Scoring Sheet'!F235)+1,20))) | K17: =J17-I17 | L17: =VALUE(TRIM(LEFT('Blind Scoring Sheet'!H235,FIND("|",'Blind Scoring Sheet'!H235)-1))) | M17: =VALUE(TRIM(MID('Blind Scoring Sheet'!H235,FIND("|",'Blind Scoring Sheet'!H235)+1,20))) | N17: =M17-L17 | O17: =VALUE(TRIM(LEFT('Blind Scoring Sheet'!J235,FIND("|",'Blind Scoring Sheet'!J235)-1))) | P17: =VALUE(TRIM(MID('Blind Scoring Sheet'!J235,FIND("|",'Blind Scoring Sheet'!J235)+1,20))) | Q17: =P17-O17 | R17: =ABS(Q17) | S17: =TRIM(LEFT('Blind Scoring Sheet'!K235,FIND("|",'Blind Scoring Sheet'!K235)-1)) | T17: =TRIM(MID('Blind Scoring Sheet'!K235,FIND("|",'Blind Scoring Sheet'!K235)+1,20)) | U17: =IF(S17=T17,"No","Yes") | V17: =IF(S17=T17,"— (agree)",S17&" → "&T17) | W17: =R17+ROW()/1000000
A18: R_0261 | B18: 264 | C18: =VALUE(TRIM(LEFT('Blind Scoring Sheet'!B264,FIND("|",'Blind Scoring Sheet'!B264)-1))) | D18: =VALUE(TRIM(MID('Blind Scoring Sheet'!B264,FIND("|",'Blind Scoring Sheet'!B264)+1,20))) | E18: =D18-C18 | F18: =VALUE(TRIM(LEFT('Blind Scoring Sheet'!D264,FIND("|",'Blind Scoring Sheet'!D264)-1))) | G18: =VALUE(TRIM(MID('Blind Scoring Sheet'!D264,FIND("|",'Blind Scoring Sheet'!D264)+1,20))) | H18: =G18-F18 | I18: =VALUE(TRIM(LEFT('Blind Scoring Sheet'!F264,FIND("|",'Blind Scoring Sheet'!F264)-1))) | J18: =VALUE(TRIM(MID('Blind Scoring Sheet'!F264,FIND("|",'Blind Scoring Sheet'!F264)+1,20))) | K18: =J18-I18 | L18: =VALUE(TRIM(LEFT('Blind Scoring Sheet'!H264,FIND("|",'Blind Scoring Sheet'!H264)-1))) | M18: =VALUE(TRIM(MID('Blind Scoring Sheet'!H264,FIND("|",'Blind Scoring Sheet'!H264)+1,20))) | N18: =M18-L18 | O18: =VALUE(TRIM(LEFT('Blind Scoring Sheet'!J264,FIND("|",'Blind Scoring Sheet'!J264)-1))) | P18: =VALUE(TRIM(MID('Blind Scoring Sheet'!J264,FIND("|",'Blind Scoring Sheet'!J264)+1,20))) | Q18: =P18-O18 | R18: =ABS(Q18) | S18: =TRIM(LEFT('Blind Scoring Sheet'!K264,FIND("|",'Blind Scoring Sheet'!K264)-1)) | T18: =TRIM(MID('Blind Scoring Sheet'!K264,FIND("|",'Blind Scoring Sheet'!K264)+1,20)) | U18: =IF(S18=T18,"No","Yes") | V18: =IF(S18=T18,"— (agree)",S18&" → "&T18) | W18: =R18+ROW()/1000000
A19: R_0285 | B19: 288 | C19: =VALUE(TRIM(LEFT('Blind Scoring Sheet'!B288,FIND("|",'Blind Scoring Sheet'!B288)-1))) | D19: =VALUE(TRIM(MID('Blind Scoring Sheet'!B288,FIND("|",'Blind Scoring Sheet'!B288)+1,20))) | E19: =D19-C19 | F19: =VALUE(TRIM(LEFT('Blind Scoring Sheet'!D288,FIND("|",'Blind Scoring Sheet'!D288)-1))) | G19: =VALUE(TRIM(MID('Blind Scoring Sheet'!D288,FIND("|",'Blind Scoring Sheet'!D288)+1,20))) | H19: =G19-F19 | I19: =VALUE(TRIM(LEFT('Blind Scoring Sheet'!F288,FIND("|",'Blind Scoring Sheet'!F288)-1))) | J19: =VALUE(TRIM(MID('Blind Scoring Sheet'!F288,FIND("|",'Blind Scoring Sheet'!F288)+1,20))) | K19: =J19-I19 | L19: =VALUE(TRIM(LEFT('Blind Scoring Sheet'!H288,FIND("|",'Blind Scoring Sheet'!H288)-1))) | M19: =VALUE(TRIM(MID('Blind Scoring Sheet'!H288,FIND("|",'Blind Scoring Sheet'!H288)+1,20))) | N19: =M19-L19 | O19: =VALUE(TRIM(LEFT('Blind Scoring Sheet'!J288,FIND("|",'Blind Scoring Sheet'!J288)-1))) | P19: =VALUE(TRIM(MID('Blind Scoring Sheet'!J288,FIND("|",'Blind Scoring Sheet'!J288)+1,20))) | Q19: =P19-O19 | R19: =ABS(Q19) | S19: =TRIM(LEFT('Blind Scoring Sheet'!K288,FIND("|",'Blind Scoring Sheet'!K288)-1)) | T19: =TRIM(MID('Blind Scoring Sheet'!K288,FIND("|",'Blind Scoring Sheet'!K288)+1,20)) | U19: =IF(S19=T19,"No","Yes") | V19: =IF(S19=T19,"— (agree)",S19&" → "&T19) | W19: =R19+ROW()/1000000
A20: R_0294 | B20: 297 | C20: =VALUE(TRIM(LEFT('Blind Scoring Sheet'!B297,FIND("|",'Blind Scoring Sheet'!B297)-1))) | D20: =VALUE(TRIM(MID('Blind Scoring Sheet'!B297,FIND("|",'Blind Scoring Sheet'!B297)+1,20))) | E20: =D20-C20 | F20: =VALUE(TRIM(LEFT('Blind Scoring Sheet'!D297,FIND("|",'Blind Scoring Sheet'!D297)-1))) | G20: =VALUE(TRIM(MID('Blind Scoring Sheet'!D297,FIND("|",'Blind Scoring Sheet'!D297)+1,20))) | H20: =G20-F20 | I20: =VALUE(TRIM(LEFT('Blind Scoring Sheet'!F297,FIND("|",'Blind Scoring Sheet'!F297)-1))) | J20: =VALUE(TRIM(MID('Blind Scoring Sheet'!F297,FIND("|",'Blind Scoring Sheet'!F297)+1,20))) | K20: =J20-I20 | L20: =VALUE(TRIM(LEFT('Blind Scoring Sheet'!H297,FIND("|",'Blind Scoring Sheet'!H297)-1))) | M20: =VALUE(TRIM(MID('Blind Scoring Sheet'!H297,FIND("|",'Blind Scoring Sheet'!H297)+1,20))) | N20: =M20-L20 | O20: =VALUE(TRIM(LEFT('Blind Scoring Sheet'!J297,FIND("|",'Blind Scoring Sheet'!J297)-1))) | P20: =VALUE(TRIM(MID('Blind Scoring Sheet'!J297,FIND("|",'Blind Scoring Sheet'!J297)+1,20))) | Q20: =P20-O20 | R20: =ABS(Q20) | S20: =TRIM(LEFT('Blind Scoring Sheet'!K297,FIND("|",'Blind Scoring Sheet'!K297)-1)) | T20: =TRIM(MID('Blind Scoring Sheet'!K297,FIND("|",'Blind Scoring Sheet'!K297)+1,20)) | U20: =IF(S20=T20,"No","Yes") | V20: =IF(S20=T20,"— (agree)",S20&" → "&T20) | W20: =R20+ROW()/1000000
A21: R_0353 | B21: 356 | C21: =VALUE(TRIM(LEFT('Blind Scoring Sheet'!B356,FIND("|",'Blind Scoring Sheet'!B356)-1))) | D21: =VALUE(TRIM(MID('Blind Scoring Sheet'!B356,FIND("|",'Blind Scoring Sheet'!B356)+1,20))) | E21: =D21-C21 | F21: =VALUE(TRIM(LEFT('Blind Scoring Sheet'!D356,FIND("|",'Blind Scoring Sheet'!D356)-1))) | G21: =VALUE(TRIM(MID('Blind Scoring Sheet'!D356,FIND("|",'Blind Scoring Sheet'!D356)+1,20))) | H21: =G21-F21 | I21: =VALUE(TRIM(LEFT('Blind Scoring Sheet'!F356,FIND("|",'Blind Scoring Sheet'!F356)-1))) | J21: =VALUE(TRIM(MID('Blind Scoring Sheet'!F356,FIND("|",'Blind Scoring Sheet'!F356)+1,20))) | K21: =J21-I21 | L21: =VALUE(TRIM(LEFT('Blind Scoring Sheet'!H356,FIND("|",'Blind Scoring Sheet'!H356)-1))) | M21: =VALUE(TRIM(MID('Blind Scoring Sheet'!H356,FIND("|",'Blind Scoring Sheet'!H356)+1,20))) | N21: =M21-L21 | O21: =VALUE(TRIM(LEFT('Blind Scoring Sheet'!J356,FIND("|",'Blind Scoring Sheet'!J356)-1))) | P21: =VALUE(TRIM(MID('Blind Scoring Sheet'!J356,FIND("|",'Blind Scoring Sheet'!J356)+1,20))) | Q21: =P21-O21 | R21: =ABS(Q21) | S21: =TRIM(LEFT('Blind Scoring Sheet'!K356,FIND("|",'Blind Scoring Sheet'!K356)-1)) | T21: =TRIM(MID('Blind Scoring Sheet'!K356,FIND("|",'Blind Scoring Sheet'!K356)+1,20)) | U21: =IF(S21=T21,"No","Yes") | V21: =IF(S21=T21,"— (agree)",S21&" → "&T21) | W21: =R21+ROW()/1000000
A22: R_0366 | B22: 369 | C22: =VALUE(TRIM(LEFT('Blind Scoring Sheet'!B369,FIND("|",'Blind Scoring Sheet'!B369)-1))) | D22: =VALUE(TRIM(MID('Blind Scoring Sheet'!B369,FIND("|",'Blind Scoring Sheet'!B369)+1,20))) | E22: =D22-C22 | F22: =VALUE(TRIM(LEFT('Blind Scoring Sheet'!D369,FIND("|",'Blind Scoring Sheet'!D369)-1))) | G22: =VALUE(TRIM(MID('Blind Scoring Sheet'!D369,FIND("|",'Blind Scoring Sheet'!D369)+1,20))) | H22: =G22-F22 | I22: =VALUE(TRIM(LEFT('Blind Scoring Sheet'!F369,FIND("|",'Blind Scoring Sheet'!F369)-1))) | J22: =VALUE(TRIM(MID('Blind Scoring Sheet'!F369,FIND("|",'Blind Scoring Sheet'!F369)+1,20))) | K22: =J22-I22 | L22: =VALUE(TRIM(LEFT('Blind Scoring Sheet'!H369,FIND("|",'Blind Scoring Sheet'!H369)-1))) | M22: =VALUE(TRIM(MID('Blind Scoring Sheet'!H369,FIND("|",'Blind Scoring Sheet'!H369)+1,20))) | N22: =M22-L22 | O22: =VALUE(TRIM(LEFT('Blind Scoring Sheet'!J369,FIND("|",'Blind Scoring Sheet'!J369)-1))) | P22: =VALUE(TRIM(MID('Blind Scoring Sheet'!J369,FIND("|",'Blind Scoring Sheet'!J369)+1,20))) | Q22: =P22-O22 | R22: =ABS(Q22) | S22: =TRIM(LEFT('Blind Scoring Sheet'!K369,FIND("|",'Blind Scoring Sheet'!K369)-1)) | T22: =TRIM(MID('Blind Scoring Sheet'!K369,FIND("|",'Blind Scoring Sheet'!K369)+1,20)) | U22: =IF(S22=T22,"No","Yes") | V22: =IF(S22=T22,"— (agree)",S22&" → "&T22) | W22: =R22+ROW()/1000000
A23: R_0390 | B23: 393 | C23: =VALUE(TRIM(LEFT('Blind Scoring Sheet'!B393,FIND("|",'Blind Scoring Sheet'!B393)-1))) | D23: =VALUE(TRIM(MID('Blind Scoring Sheet'!B393,FIND("|",'Blind Scoring Sheet'!B393)+1,20))) | E23: =D23-C23 | F23: =VALUE(TRIM(LEFT('Blind Scoring Sheet'!D393,FIND("|",'Blind Scoring Sheet'!D393)-1))) | G23: =VALUE(TRIM(MID('Blind Scoring Sheet'!D393,FIND("|",'Blind Scoring Sheet'!D393)+1,20))) | H23: =G23-F23 | I23: =VALUE(TRIM(LEFT('Blind Scoring Sheet'!F393,FIND("|",'Blind Scoring Sheet'!F393)-1))) | J23: =VALUE(TRIM(MID('Blind Scoring Sheet'!F393,FIND("|",'Blind Scoring Sheet'!F393)+1,20))) | K23: =J23-I23 | L23: =VALUE(TRIM(LEFT('Blind Scoring Sheet'!H393,FIND("|",'Blind Scoring Sheet'!H393)-1))) | M23: =VALUE(TRIM(MID('Blind Scoring Sheet'!H393,FIND("|",'Blind Scoring Sheet'!H393)+1,20))) | N23: =M23-L23 | O23: =VALUE(TRIM(LEFT('Blind Scoring Sheet'!J393,FIND("|",'Blind Scoring Sheet'!J393)-1))) | P23: =VALUE(TRIM(MID('Blind Scoring Sheet'!J393,FIND("|",'Blind Scoring Sheet'!J393)+1,20))) | Q23: =P23-O23 | R23: =ABS(Q23) | S23: =TRIM(LEFT('Blind Scoring Sheet'!K393,FIND("|",'Blind Scoring Sheet'!K393)-1)) | T23: =TRIM(MID('Blind Scoring Sheet'!K393,FIND("|",'Blind Scoring Sheet'!K393)+1,20)) | U23: =IF(S23=T23,"No","Yes") | V23: =IF(S23=T23,"— (agree)",S23&" → "&T23) | W23: =R23+ROW()/1000000
A24: R_0393 | B24: 396 | C24: =VALUE(TRIM(LEFT('Blind Scoring Sheet'!B396,FIND("|",'Blind Scoring Sheet'!B396)-1))) | D24: =VALUE(TRIM(MID('Blind Scoring Sheet'!B396,FIND("|",'Blind Scoring Sheet'!B396)+1,20))) | E24: =D24-C24 | F24: =VALUE(TRIM(LEFT('Blind Scoring Sheet'!D396,FIND("|",'Blind Scoring Sheet'!D396)-1))) | G24: =VALUE(TRIM(MID('Blind Scoring Sheet'!D396,FIND("|",'Blind Scoring Sheet'!D396)+1,20))) | H24: =G24-F24 | I24: =VALUE(TRIM(LEFT('Blind Scoring Sheet'!F396,FIND("|",'Blind Scoring Sheet'!F396)-1))) | J24: =VALUE(TRIM(MID('Blind Scoring Sheet'!F396,FIND("|",'Blind Scoring Sheet'!F396)+1,20))) | K24: =J24-I24 | L24: =VALUE(TRIM(LEFT('Blind Scoring Sheet'!H396,FIND("|",'Blind Scoring Sheet'!H396)-1))) | M24: =VALUE(TRIM(MID('Blind Scoring Sheet'!H396,FIND("|",'Blind Scoring Sheet'!H396)+1,20))) | N24: =M24-L24 | O24: =VALUE(TRIM(LEFT('Blind Scoring Sheet'!J396,FIND("|",'Blind Scoring Sheet'!J396)-1))) | P24: =VALUE(TRIM(MID('Blind Scoring Sheet'!J396,FIND("|",'Blind Scoring Sheet'!J396)+1,20))) | Q24: =P24-O24 | R24: =ABS(Q24) | S24: =TRIM(LEFT('Blind Scoring Sheet'!K396,FIND("|",'Blind Scoring Sheet'!K396)-1)) | T24: =TRIM(MID('Blind Scoring Sheet'!K396,FIND("|",'Blind Scoring Sheet'!K396)+1,20)) | U24: =IF(S24=T24,"No","Yes") | V24: =IF(S24=T24,"— (agree)",S24&" → "&T24) | W24: =R24+ROW()/1000000
A25: R_0397 | B25: 400 | C25: =VALUE(TRIM(LEFT('Blind Scoring Sheet'!B400,FIND("|",'Blind Scoring Sheet'!B400)-1))) | D25: =VALUE(TRIM(MID('Blind Scoring Sheet'!B400,FIND("|",'Blind Scoring Sheet'!B400)+1,20))) | E25: =D25-C25 | F25: =VALUE(TRIM(LEFT('Blind Scoring Sheet'!D400,FIND("|",'Blind Scoring Sheet'!D400)-1))) | G25: =VALUE(TRIM(MID('Blind Scoring Sheet'!D400,FIND("|",'Blind Scoring Sheet'!D400)+1,20))) | H25: =G25-F25 | I25: =VALUE(TRIM(LEFT('Blind Scoring Sheet'!F400,FIND("|",'Blind Scoring Sheet'!F400)-1))) | J25: =VALUE(TRIM(MID('Blind Scoring Sheet'!F400,FIND("|",'Blind Scoring Sheet'!F400)+1,20))) | K25: =J25-I25 | L25: =VALUE(TRIM(LEFT('Blind Scoring Sheet'!H400,FIND("|",'Blind Scoring Sheet'!H400)-1))) | M25: =VALUE(TRIM(MID('Blind Scoring Sheet'!H400,FIND("|",'Blind Scoring Sheet'!H400)+1,20))) | N25: =M25-L25 | O25: =VALUE(TRIM(LEFT('Blind Scoring Sheet'!J400,FIND("|",'Blind Scoring Sheet'!J400)-1))) | P25: =VALUE(TRIM(MID('Blind Scoring Sheet'!J400,FIND("|",'Blind Scoring Sheet'!J400)+1,20))) | Q25: =P25-O25 | R25: =ABS(Q25) | S25: =TRIM(LEFT('Blind Scoring Sheet'!K400,FIND("|",'Blind Scoring Sheet'!K400)-1)) | T25: =TRIM(MID('Blind Scoring Sheet'!K400,FIND("|",'Blind Scoring Sheet'!K400)+1,20)) | U25: =IF(S25=T25,"No","Yes") | V25: =IF(S25=T25,"— (agree)",S25&" → "&T25) | W25: =R25+ROW()/1000000
A26: R_0435 | B26: 438 | C26: =VALUE(TRIM(LEFT('Blind Scoring Sheet'!B438,FIND("|",'Blind Scoring Sheet'!B438)-1))) | D26: =VALUE(TRIM(MID('Blind Scoring Sheet'!B438,FIND("|",'Blind Scoring Sheet'!B438)+1,20))) | E26: =D26-C26 | F26: =VALUE(TRIM(LEFT('Blind Scoring Sheet'!D438,FIND("|",'Blind Scoring Sheet'!D438)-1))) | G26: =VALUE(TRIM(MID('Blind Scoring Sheet'!D438,FIND("|",'Blind Scoring Sheet'!D438)+1,20))) | H26: =G26-F26 | I26: =VALUE(TRIM(LEFT('Blind Scoring Sheet'!F438,FIND("|",'Blind Scoring Sheet'!F438)-1))) | J26: =VALUE(TRIM(MID('Blind Scoring Sheet'!F438,FIND("|",'Blind Scoring Sheet'!F438)+1,20))) | K26: =J26-I26 | L26: =VALUE(TRIM(LEFT('Blind Scoring Sheet'!H438,FIND("|",'Blind Scoring Sheet'!H438)-1))) | M26: =VALUE(TRIM(MID('Blind Scoring Sheet'!H438,FIND("|",'Blind Scoring Sheet'!H438)+1,20))) | N26: =M26-L26 | O26: =VALUE(TRIM(LEFT('Blind Scoring Sheet'!J438,FIND("|",'Blind Scoring Sheet'!J438)-1))) | P26: =VALUE(TRIM(MID('Blind Scoring Sheet'!J438,FIND("|",'Blind Scoring Sheet'!J438)+1,20))) | Q26: =P26-O26 | R26: =ABS(Q26) | S26: =TRIM(LEFT('Blind Scoring Sheet'!K438,FIND("|",'Blind Scoring Sheet'!K438)-1)) | T26: =TRIM(MID('Blind Scoring Sheet'!K438,FIND("|",'Blind Scoring Sheet'!K438)+1,20)) | U26: =IF(S26=T26,"No","Yes") | V26: =IF(S26=T26,"— (agree)",S26&" → "&T26) | W26: =R26+ROW()/1000000
A27: R_0439 | B27: 442 | C27: =VALUE(TRIM(LEFT('Blind Scoring Sheet'!B442,FIND("|",'Blind Scoring Sheet'!B442)-1))) | D27: =VALUE(TRIM(MID('Blind Scoring Sheet'!B442,FIND("|",'Blind Scoring Sheet'!B442)+1,20))) | E27: =D27-C27 | F27: =VALUE(TRIM(LEFT('Blind Scoring Sheet'!D442,FIND("|",'Blind Scoring Sheet'!D442)-1))) | G27: =VALUE(TRIM(MID('Blind Scoring Sheet'!D442,FIND("|",'Blind Scoring Sheet'!D442)+1,20))) | H27: =G27-F27 | I27: =VALUE(TRIM(LEFT('Blind Scoring Sheet'!F442,FIND("|",'Blind Scoring Sheet'!F442)-1))) | J27: =VALUE(TRIM(MID('Blind Scoring Sheet'!F442,FIND("|",'Blind Scoring Sheet'!F442)+1,20))) | K27: =J27-I27 | L27: =VALUE(TRIM(LEFT('Blind Scoring Sheet'!H442,FIND("|",'Blind Scoring Sheet'!H442)-1))) | M27: =VALUE(TRIM(MID('Blind Scoring Sheet'!H442,FIND("|",'Blind Scoring Sheet'!H442)+1,20))) | N27: =M27-L27 | O27: =VALUE(TRIM(LEFT('Blind Scoring Sheet'!J442,FIND("|",'Blind Scoring Sheet'!J442)-1))) | P27: =VALUE(TRIM(MID('Blind Scoring Sheet'!J442,FIND("|",'Blind Scoring Sheet'!J442)+1,20))) | Q27: =P27-O27 | R27: =ABS(Q27) | S27: =TRIM(LEFT('Blind Scoring Sheet'!K442,FIND("|",'Blind Scoring Sheet'!K442)-1)) | T27: =TRIM(MID('Blind Scoring Sheet'!K442,FIND("|",'Blind Scoring Sheet'!K442)+1,20)) | U27: =IF(S27=T27,"No","Yes") | V27: =IF(S27=T27,"— (agree)",S27&" → "&T27) | W27: =R27+ROW()/1000000
A28: R_0472 | B28: 475 | C28: =VALUE(TRIM(LEFT('Blind Scoring Sheet'!B475,FIND("|",'Blind Scoring Sheet'!B475)-1))) | D28: =VALUE(TRIM(MID('Blind Scoring Sheet'!B475,FIND("|",'Blind Scoring Sheet'!B475)+1,20))) | E28: =D28-C28 | F28: =VALUE(TRIM(LEFT('Blind Scoring Sheet'!D475,FIND("|",'Blind Scoring Sheet'!D475)-1))) | G28: =VALUE(TRIM(MID('Blind Scoring Sheet'!D475,FIND("|",'Blind Scoring Sheet'!D475)+1,20))) | H28: =G28-F28 | I28: =VALUE(TRIM(LEFT('Blind Scoring Sheet'!F475,FIND("|",'Blind Scoring Sheet'!F475)-1))) | J28: =VALUE(TRIM(MID('Blind Scoring Sheet'!F475,FIND("|",'Blind Scoring Sheet'!F475)+1,20))) | K28: =J28-I28 | L28: =VALUE(TRIM(LEFT('Blind Scoring Sheet'!H475,FIND("|",'Blind Scoring Sheet'!H475)-1))) | M28: =VALUE(TRIM(MID('Blind Scoring Sheet'!H475,FIND("|",'Blind Scoring Sheet'!H475)+1,20))) | N28: =M28-L28 | O28: =VALUE(TRIM(LEFT('Blind Scoring Sheet'!J475,FIND("|",'Blind Scoring Sheet'!J475)-1))) | P28: =VALUE(TRIM(MID('Blind Scoring Sheet'!J475,FIND("|",'Blind Scoring Sheet'!J475)+1,20))) | Q28: =P28-O28 | R28: =ABS(Q28) | S28: =TRIM(LEFT('Blind Scoring Sheet'!K475,FIND("|",'Blind Scoring Sheet'!K475)-1)) | T28: =TRIM(MID('Blind Scoring Sheet'!K475,FIND("|",'Blind Scoring Sheet'!K475)+1,20)) | U28: =IF(S28=T28,"No","Yes") | V28: =IF(S28=T28,"— (agree)",S28&" → "&T28) | W28: =R28+ROW()/1000000
A29: R_0473 | B29: 476 | C29: =VALUE(TRIM(LEFT('Blind Scoring Sheet'!B476,FIND("|",'Blind Scoring Sheet'!B476)-1))) | D29: =VALUE(TRIM(MID('Blind Scoring Sheet'!B476,FIND("|",'Blind Scoring Sheet'!B476)+1,20))) | E29: =D29-C29 | F29: =VALUE(TRIM(LEFT('Blind Scoring Sheet'!D476,FIND("|",'Blind Scoring Sheet'!D476)-1))) | G29: =VALUE(TRIM(MID('Blind Scoring Sheet'!D476,FIND("|",'Blind Scoring Sheet'!D476)+1,20))) | H29: =G29-F29 | I29: =VALUE(TRIM(LEFT('Blind Scoring Sheet'!F476,FIND("|",'Blind Scoring Sheet'!F476)-1))) | J29: =VALUE(TRIM(MID('Blind Scoring Sheet'!F476,FIND("|",'Blind Scoring Sheet'!F476)+1,20))) | K29: =J29-I29 | L29: =VALUE(TRIM(LEFT('Blind Scoring Sheet'!H476,FIND("|",'Blind Scoring Sheet'!H476)-1))) | M29: =VALUE(TRIM(MID('Blind Scoring Sheet'!H476,FIND("|",'Blind Scoring Sheet'!H476)+1,20))) | N29: =M29-L29 | O29: =VALUE(TRIM(LEFT('Blind Scoring Sheet'!J476,FIND("|",'Blind Scoring Sheet'!J476)-1))) | P29: =VALUE(TRIM(MID('Blind Scoring Sheet'!J476,FIND("|",'Blind Scoring Sheet'!J476)+1,20))) | Q29: =P29-O29 | R29: =ABS(Q29) | S29: =TRIM(LEFT('Blind Scoring Sheet'!K476,FIND("|",'Blind Scoring Sheet'!K476)-1)) | T29: =TRIM(MID('Blind Scoring Sheet'!K476,FIND("|",'Blind Scoring Sheet'!K476)+1,20)) | U29: =IF(S29=T29,"No","Yes") | V29: =IF(S29=T29,"— (agree)",S29&" → "&T29) | W29: =R29+ROW()/1000000
A30: R_0474 | B30: 477 | C30: =VALUE(TRIM(LEFT('Blind Scoring Sheet'!B477,FIND("|",'Blind Scoring Sheet'!B477)-1))) | D30: =VALUE(TRIM(MID('Blind Scoring Sheet'!B477,FIND("|",'Blind Scoring Sheet'!B477)+1,20))) | E30: =D30-C30 | F30: =VALUE(TRIM(LEFT('Blind Scoring Sheet'!D477,FIND("|",'Blind Scoring Sheet'!D477)-1))) | G30: =VALUE(TRIM(MID('Blind Scoring Sheet'!D477,FIND("|",'Blind Scoring Sheet'!D477)+1,20))) | H30: =G30-F30 | I30: =VALUE(TRIM(LEFT('Blind Scoring Sheet'!F477,FIND("|",'Blind Scoring Sheet'!F477)-1))) | J30: =VALUE(TRIM(MID('Blind Scoring Sheet'!F477,FIND("|",'Blind Scoring Sheet'!F477)+1,20))) | K30: =J30-I30 | L30: =VALUE(TRIM(LEFT('Blind Scoring Sheet'!H477,FIND("|",'Blind Scoring Sheet'!H477)-1))) | M30: =VALUE(TRIM(MID('Blind Scoring Sheet'!H477,FIND("|",'Blind Scoring Sheet'!H477)+1,20))) | N30: =M30-L30 | O30: =VALUE(TRIM(LEFT('Blind Scoring Sheet'!J477,FIND("|",'Blind Scoring Sheet'!J477)-1))) | P30: =VALUE(TRIM(MID('Blind Scoring Sheet'!J477,FIND("|",'Blind Scoring Sheet'!J477)+1,20))) | Q30: =P30-O30 | R30: =ABS(Q30) | S30: =TRIM(LEFT('Blind Scoring Sheet'!K477,FIND("|",'Blind Scoring Sheet'!K477)-1)) | T30: =TRIM(MID('Blind Scoring Sheet'!K477,FIND("|",'Blind Scoring Sheet'!K477)+1,20)) | U30: =IF(S30=T30,"No","Yes") | V30: =IF(S30=T30,"— (agree)",S30&" → "&T30) | W30: =R30+ROW()/1000000
A31: R_0476 | B31: 479 | C31: =VALUE(TRIM(LEFT('Blind Scoring Sheet'!B479,FIND("|",'Blind Scoring Sheet'!B479)-1))) | D31: =VALUE(TRIM(MID('Blind Scoring Sheet'!B479,FIND("|",'Blind Scoring Sheet'!B479)+1,20))) | E31: =D31-C31 | F31: =VALUE(TRIM(LEFT('Blind Scoring Sheet'!D479,FIND("|",'Blind Scoring Sheet'!D479)-1))) | G31: =VALUE(TRIM(MID('Blind Scoring Sheet'!D479,FIND("|",'Blind Scoring Sheet'!D479)+1,20))) | H31: =G31-F31 | I31: =VALUE(TRIM(LEFT('Blind Scoring Sheet'!F479,FIND("|",'Blind Scoring Sheet'!F479)-1))) | J31: =VALUE(TRIM(MID('Blind Scoring Sheet'!F479,FIND("|",'Blind Scoring Sheet'!F479)+1,20))) | K31: =J31-I31 | L31: =VALUE(TRIM(LEFT('Blind Scoring Sheet'!H479,FIND("|",'Blind Scoring Sheet'!H479)-1))) | M31: =VALUE(TRIM(MID('Blind Scoring Sheet'!H479,FIND("|",'Blind Scoring Sheet'!H479)+1,20))) | N31: =M31-L31 | O31: =VALUE(TRIM(LEFT('Blind Scoring Sheet'!J479,FIND("|",'Blind Scoring Sheet'!J479)-1))) | P31: =VALUE(TRIM(MID('Blind Scoring Sheet'!J479,FIND("|",'Blind Scoring Sheet'!J479)+1,20))) | Q31: =P31-O31 | R31: =ABS(Q31) | S31: =TRIM(LEFT('Blind Scoring Sheet'!K479,FIND("|",'Blind Scoring Sheet'!K479)-1)) | T31: =TRIM(MID('Blind Scoring Sheet'!K479,FIND("|",'Blind Scoring Sheet'!K479)+1,20)) | U31: =IF(S31=T31,"No","Yes") | V31: =IF(S31=T31,"— (agree)",S31&" → "&T31) | W31: =R31+ROW()/1000000
A32: R_0486 | B32: 489 | C32: =VALUE(TRIM(LEFT('Blind Scoring Sheet'!B489,FIND("|",'Blind Scoring Sheet'!B489)-1))) | D32: =VALUE(TRIM(MID('Blind Scoring Sheet'!B489,FIND("|",'Blind Scoring Sheet'!B489)+1,20))) | E32: =D32-C32 | F32: =VALUE(TRIM(LEFT('Blind Scoring Sheet'!D489,FIND("|",'Blind Scoring Sheet'!D489)-1))) | G32: =VALUE(TRIM(MID('Blind Scoring Sheet'!D489,FIND("|",'Blind Scoring Sheet'!D489)+1,20))) | H32: =G32-F32 | I32: =VALUE(TRIM(LEFT('Blind Scoring Sheet'!F489,FIND("|",'Blind Scoring Sheet'!F489)-1))) | J32: =VALUE(TRIM(MID('Blind Scoring Sheet'!F489,FIND("|",'Blind Scoring Sheet'!F489)+1,20))) | K32: =J32-I32 | L32: =VALUE(TRIM(LEFT('Blind Scoring Sheet'!H489,FIND("|",'Blind Scoring Sheet'!H489)-1))) | M32: =VALUE(TRIM(MID('Blind Scoring Sheet'!H489,FIND("|",'Blind Scoring Sheet'!H489)+1,20))) | N32: =M32-L32 | O32: =VALUE(TRIM(LEFT('Blind Scoring Sheet'!J489,FIND("|",'Blind Scoring Sheet'!J489)-1))) | P32: =VALUE(TRIM(MID('Blind Scoring Sheet'!J489,FIND("|",'Blind Scoring Sheet'!J489)+1,20))) | Q32: =P32-O32 | R32: =ABS(Q32) | S32: =TRIM(LEFT('Blind Scoring Sheet'!K489,FIND("|",'Blind Scoring Sheet'!K489)-1)) | T32: =TRIM(MID('Blind Scoring Sheet'!K489,FIND("|",'Blind Scoring Sheet'!K489)+1,20)) | U32: =IF(S32=T32,"No","Yes") | V32: =IF(S32=T32,"— (agree)",S32&" → "&T32) | W32: =R32+ROW()/1000000
